<?xml version='1.0'?>
<sdf version='1.4'>
  <model name='Skywalker_2013_mk3'>
    <link name='fuselage'>
      <pose frame=''>0 0 0 0 -0 0</pose>
      <inertial>
        <mass>2</mass>
        <inertia>
          <ixx>0.8244</ixx>
          <ixy>0</ixy>
          <ixz>0.1204</ixz>
          <iyy>1.135</iyy>
          <iyz>0</iyz>
          <izz>1.759</izz>
        </inertia>
        <pose frame=''>0 0 0 0 -0 0</pose>
      </inertial>
      <self_collide>0</self_collide>
      <kinematic>0</kinematic>
      <visual name='visual'>
        <pose frame=''>0 0 0 -3.14149 0 0</pose>
        <geometry>
          <mesh>
            <uri>/home/george/model_editor_models/Skywalker_2013_mk2/meshes/skywalker_2013.dae</uri>
          </mesh>
        </geometry>
        <material>
          <lighting>1</lighting>
          <script>
            <uri>file://media/materials/scripts/gazebo.material</uri>
            <name>Gazebo/Grey</name>
          </script>
          <ambient>0.3 0.3 0.3 1</ambient>
          <diffuse>0.7 0.7 0.7 1</diffuse>
          <specular>0.01 0.01 0.01 1</specular>
          <emissive>0 0 0 1</emissive>
          <shader type='vertex'>
            <normal_map>__default__</normal_map>
          </shader>
        </material>
        <cast_shadows>1</cast_shadows>
        <transparency>0</transparency>
      </visual>
      <collision name='fuselage'>
        <laser_retro>0</laser_retro>
        <max_contacts>10</max_contacts>
        <pose frame=''>-0.27 0 0 0 0 0</pose>
        <geometry>
          <box>
            <size>1.24351 0.141476 0.176851</size>
          </box>
        </geometry>
        <surface>
          <friction>
            <ode>
              <mu>1</mu>
              <mu2>1</mu2>
              <fdir1>0 0 0</fdir1>
              <slip1>0</slip1>
              <slip2>0</slip2>
            </ode>
            <torsional>
              <coefficient>1</coefficient>
              <patch_radius>0</patch_radius>
              <surface_radius>0</surface_radius>
              <use_patch_radius>1</use_patch_radius>
              <ode>
                <slip>0</slip>
              </ode>
            </torsional>
          </friction>
          <bounce>
            <restitution_coefficient>0</restitution_coefficient>
            <threshold>1e+06</threshold>
          </bounce>
          <contact>
            <collide_without_contact>0</collide_without_contact>
            <collide_without_contact_bitmask>1</collide_without_contact_bitmask>
            <collide_bitmask>1</collide_bitmask>
            <ode>
              <soft_cfm>0</soft_cfm>
              <soft_erp>0.2</soft_erp>
              <kp>1e+13</kp>
              <kd>1</kd>
              <max_vel>0.01</max_vel>
              <min_depth>0</min_depth>
            </ode>
            <bullet>
              <split_impulse>1</split_impulse>
              <split_impulse_penetration_threshold>-0.01</split_impulse_penetration_threshold>
              <soft_cfm>0</soft_cfm>
              <soft_erp>0.2</soft_erp>
              <kp>1e+13</kp>
              <kd>1</kd>
            </bullet>
          </contact>
        </surface>
      </collision>
      <collision name='main_wing'>
        <laser_retro>0</laser_retro>
        <max_contacts>10</max_contacts>
        <pose frame=''>-0.02 0 0.15 0 -0 0</pose>
        <geometry>
          <box>
            <size>0.25 1.9 0.05</size>
          </box>
        </geometry>
        <surface>
          <friction>
            <ode>
              <mu>0.4</mu>
              <mu2>0.4</mu2>
              <fdir1>0 0 0</fdir1>
              <slip1>0</slip1>
              <slip2>0</slip2>
            </ode>
            <torsional>
              <coefficient>1</coefficient>
              <patch_radius>0</patch_radius>
              <surface_radius>0</surface_radius>
              <use_patch_radius>1</use_patch_radius>
              <ode>
                <slip>0</slip>
              </ode>
            </torsional>
          </friction>
          <bounce>
            <restitution_coefficient>0</restitution_coefficient>
            <threshold>1e+06</threshold>
          </bounce>
          <contact>
            <collide_without_contact>0</collide_without_contact>
            <collide_without_contact_bitmask>1</collide_without_contact_bitmask>
            <collide_bitmask>1</collide_bitmask>
            <ode>
              <soft_cfm>0</soft_cfm>
              <soft_erp>0.2</soft_erp>
              <kp>1e+13</kp>
              <kd>1</kd>
              <max_vel>0.01</max_vel>
              <min_depth>0</min_depth>
            </ode>
            <bullet>
              <split_impulse>1</split_impulse>
              <split_impulse_penetration_threshold>-0.01</split_impulse_penetration_threshold>
              <soft_cfm>0</soft_cfm>
              <soft_erp>0.2</soft_erp>
              <kp>1e+13</kp>
              <kd>1</kd>
            </bullet>
          </contact>
        </surface>
      </collision>
    </link>

    <link name="left_wheel">
      <pose>0.15 0.22 -0.18 0 1.5707 1.5707</pose>
      <inertial>
        <mass>0.010</mass>
        <inertia>
          <ixx>0.0075</ixx>
          <ixy>0</ixy>
          <ixz>0</ixz>
          <iyy>0.0075</iyy>
          <iyz>0</iyz>
          <izz>0.000016</izz>
        </inertia>
        <pose frame=''>0 0 0 0 -0 0</pose>
      </inertial>

<!--       <collision name="collision">
        <geometry>
          <cylinder>
            <radius>.04</radius>
            <length>.03</length>
          </cylinder>
        </geometry>
      </collision> -->

<collision name='collision'>
        <laser_retro>0</laser_retro>
        <max_contacts>10</max_contacts>
        <pose frame=''>0 0 0 0 -0 0</pose>
        <geometry>
          <cylinder>
            <radius>0.04</radius>
            <length>0.03</length>
          </cylinder>
        </geometry>
        <surface>
          <friction>
            <ode>
              <mu>0</mu>
              <mu2>0</mu2>
              <fdir1>0 0 0</fdir1>
              <slip1>1</slip1>
              <slip2>1</slip2>
            </ode>
            <torsional>
              <coefficient>1</coefficient>
              <patch_radius>0</patch_radius>
              <surface_radius>0</surface_radius>
              <use_patch_radius>1</use_patch_radius>
              <ode>
                <slip>0</slip>
              </ode>
            </torsional>
          </friction>
          <bounce>
            <restitution_coefficient>0</restitution_coefficient>
            <threshold>1e+06</threshold>
          </bounce>
          <contact>
            <collide_without_contact>0</collide_without_contact>
            <collide_without_contact_bitmask>1</collide_without_contact_bitmask>
            <collide_bitmask>1</collide_bitmask>
            <ode>
              <soft_cfm>0</soft_cfm>
              <soft_erp>0.2</soft_erp>
              <kp>1e+13</kp>
              <kd>1</kd>
              <max_vel>0.01</max_vel>
              <min_depth>0</min_depth>
            </ode>
            <bullet>
              <split_impulse>1</split_impulse>
              <split_impulse_penetration_threshold>-0.01</split_impulse_penetration_threshold>
              <soft_cfm>0</soft_cfm>
              <soft_erp>0.2</soft_erp>
              <kp>1e+13</kp>
              <kd>1</kd>
            </bullet>
          </contact>
        </surface>
      </collision>

      <visual name="visual">
        <geometry>
          <cylinder>
            <radius>.04</radius>
            <length>.03</length>
          </cylinder>
        </geometry>
      </visual>
    </link>

    <link name="right_wheel">
      <pose>0.15 -0.22 -0.18 0 1.5707 1.5707</pose>
      <inertial>
        <mass>0.01</mass>
        <inertia>
          <ixx>0.0075</ixx>
          <ixy>0</ixy>
          <ixz>0</ixz>
          <iyy>0.0075</iyy>
          <iyz>0</iyz>
          <izz>0.000016</izz>
        </inertia>
        <pose frame=''>0 0 0 0 -0 0</pose>
      </inertial>


<!--       <collision name="collision">
        <geometry>
          <cylinder>
            <radius>.04</radius>
            <length>.03</length>
          </cylinder>
        </geometry>
      </collision> -->
<collision name='collision'>
        <laser_retro>0</laser_retro>
        <max_contacts>10</max_contacts>
        <pose frame=''>0 0 0 0 -0 0</pose>
        <geometry>
          <cylinder>
            <radius>0.04</radius>
            <length>0.03</length>
          </cylinder>
        </geometry>
        <surface>
          <friction>
            <ode>
              <mu>0</mu>
              <mu2>0</mu2>
              <fdir1>0 0 0</fdir1>
              <slip1>1</slip1>
              <slip2>1</slip2>
            </ode>
            <torsional>
              <coefficient>1</coefficient>
              <patch_radius>0</patch_radius>
              <surface_radius>0</surface_radius>
              <use_patch_radius>1</use_patch_radius>
              <ode>
                <slip>0</slip>
              </ode>
            </torsional>
          </friction>
          <bounce>
            <restitution_coefficient>0</restitution_coefficient>
            <threshold>1e+06</threshold>
          </bounce>
          <contact>
            <collide_without_contact>0</collide_without_contact>
            <collide_without_contact_bitmask>1</collide_without_contact_bitmask>
            <collide_bitmask>1</collide_bitmask>
            <ode>
              <soft_cfm>0</soft_cfm>
              <soft_erp>0.2</soft_erp>
              <kp>1e+13</kp>
              <kd>1</kd>
              <max_vel>0.01</max_vel>
              <min_depth>0</min_depth>
            </ode>
            <bullet>
              <split_impulse>1</split_impulse>
              <split_impulse_penetration_threshold>-0.01</split_impulse_penetration_threshold>
              <soft_cfm>0</soft_cfm>
              <soft_erp>0.2</soft_erp>
              <kp>1e+13</kp>
              <kd>1</kd>
            </bullet>
          </contact>
        </surface>
      </collision>

      <visual name="visual">
        <geometry>
          <cylinder>
            <radius>.04</radius>
            <length>.03</length>
          </cylinder>
        </geometry>
      </visual>
    </link>

    <joint type="revolute" name="left_wheel_axis">
      <pose>0 0 0 0 0 0</pose>
      <child>left_wheel</child>
      <parent>fuselage</parent>
      <axis>
        <xyz>0 -1 0</xyz>
      </axis>
    </joint>

    <joint type="revolute" name="right_wheel_axis">
      <pose>0 0 0 0 0 0</pose>
      <child>right_wheel</child>
      <parent>fuselage</parent>
      <axis>
        <xyz>0 1 0</xyz>
      </axis>
    </joint>

    <link name='motor'>
      <pose frame=''>-0.25 0 0.13 3.14159 0 0</pose>
      <inertial>
        <mass>0.00221677</mass>
        <inertia>
          <ixx>1.196e-05</ixx>
          <ixy>0</ixy>
          <ixz>0</ixz>
          <iyy>1.196e-05</iyy>
          <iyz>0</iyz>
          <izz>2.55e-06</izz>
        </inertia>
        <pose frame=''>0 0 0 0 -0 0</pose>
      </inertial>
      <self_collide>0</self_collide>
      <kinematic>0</kinematic>
      <visual name='visual'>
        <pose frame=''>0 0 0 0 1.57079 0</pose>
        <geometry>
          <cylinder>
            <radius>0.04</radius>
            <length>0.04</length>
          </cylinder>
        </geometry>
        <material>
          <lighting>1</lighting>
          <script>
            <uri>file://media/materials/scripts/gazebo.material</uri>
            <name>Gazebo/Grey</name>
          </script>
          <ambient>0.3 0.3 0.3 1</ambient>
          <diffuse>0.7 0.7 0.7 1</diffuse>
          <specular>0.01 0.01 0.01 1</specular>
          <emissive>0 0 0 1</emissive>
          <shader type='vertex'>
            <normal_map>__default__</normal_map>
          </shader>
        </material>
        <cast_shadows>1</cast_shadows>
        <transparency>0</transparency>
      </visual>
    </link>

    <joint type="fixed" name="motor_mount">
      <pose>0 0 0 0 0 0</pose>
      <child>motor</child>
      <parent>fuselage</parent>
      <axis>
        <xyz>1 0 0</xyz>
      </axis>
    </joint>

    <link name='propeller'>
      <pose frame=''>-0.275 0 0.13 0 -0 0</pose>
      <inertial>
        <mass>0.003</mass>
        <inertia>
          <ixx>50.7e-6</ixx>
          <ixy>0</ixy>
          <ixz>0</ixz>
          <iyy>25e-9</iyy>
          <iyz>0</iyz>
          <izz>25e-9</izz>
        </inertia>
        <pose frame=''>0 0 0 0 -0 0</pose>
      </inertial>
      <self_collide>0</self_collide>
      <kinematic>0</kinematic>
      <visual name='visual'>
        <pose frame=''>0 0 0 0 -0 0</pose>
        <geometry>
          <mesh>
            <uri>model://Skywalker_2013_mk2/meshes/10x4_7.dae</uri>
          </mesh>
        </geometry>
        <material>
          <lighting>1</lighting>
          <script>
            <uri>file://media/materials/scripts/gazebo.material</uri>
            <name>Gazebo/Grey</name>
          </script>
          <ambient>0.3 0.3 0.3 1</ambient>
          <diffuse>0.7 0.7 0.7 1</diffuse>
          <specular>0.01 0.01 0.01 1</specular>
          <emissive>0 0 0 1</emissive>
          <shader type='vertex'>
            <normal_map>__default__</normal_map>
          </shader>
        </material>
        <cast_shadows>1</cast_shadows>
        <transparency>0</transparency>
      </visual>
      <collision name='collision'>
        <laser_retro>0</laser_retro>
        <max_contacts>10</max_contacts>
        <pose frame=''>0 0 0 0 1.57 0</pose>
        <geometry>
          <cylinder>
            <radius>0.13</radius>
            <length>0.01</length>
          </cylinder>
        </geometry>
      </collision>
    </link>

    <joint type="revolute" name="propeller_shaft">
      <pose>0 0 0 0 0 0</pose>
      <child>propeller</child>
      <parent>motor</parent>
      <axis>
        <xyz>1 0 0</xyz>
      </axis>
    </joint>

    <link name="INS">
      <pose>0 0 0 3.14159 0 0</pose>
      <inertial>
        <mass>0.001</mass>
        <inertia>
          <ixx>0.0000166667</ixx>
          <ixy>0</ixy>
          <ixz>0</ixz>
          <iyy>0.0000166667</iyy>
          <iyz>0</iyz>
          <izz>0.0000166667</izz>
        </inertia>
        <pose frame=''>0 0 0 0 -0 0</pose>
      </inertial>
      <visual name="visual">
        <geometry>
          <box>
            <size>0.1 0.1 0.1</size>
          </box>
        </geometry>
      </visual>
    </link>

    <joint type="fixed" name="INS_mount">
      <pose>0 0 0 0 0 0</pose>
      <child>INS</child>
      <parent>fuselage</parent>
      <axis>
        <xyz>1 0 0</xyz>
      </axis>
      <physics>
        <ode>
          <limit>
            <cfm>0</cfm>
            <erp>0.8</erp>
          </limit>
          <suspension>
            <cfm>0</cfm>
            <erp>0.8</erp>
          </suspension>
        </ode>
      </physics>
    </joint>

<!--     <include>
      <uri>model://hokuyo</uri>
      <pose>0.2 0 0.17 1.57079 1.57079 0</pose>
    </include>
    <joint name="hokuyo_joint" type="fixed">
      <child>hokuyo::link</child>
      <parent>fuselage</parent>
      <axis>
        <xyz>0 0 1</xyz>
      </axis>
    </joint> -->

    <!-- Plugin Insertion -->
    <plugin name="modelStatePublisher" filename="libmodel_state_publisher.so"/>
    <plugin name="engineControl" filename="libengine_control.so"/>
    <plugin name="engineControl" filename="libaerodynamics.so"/>
    <plugin name="chaseCamera" filename="libchase_camera.so"/>

    <static>0</static>
    <allow_auto_disable>1</allow_auto_disable>
  </model>
</sdf>
