<?xml version="1.0"?>

<robot name="quad">
	<link name="base_link">
		<visual>
			<origin rpy="-1.57 0 0"/>
			<geometry>
				<mesh filename="package://last_letter/data/parameters/aircraft/quadrotor/urdf/quadrotor.stl" scale="0.0015 0.0015 0.0015"/>
			</geometry>
			<material name="blueCuriosity">
				<color rgba="0.0 0.2 0.8 1"/>
			</material>
		</visual>
	</link>

	<link name="propeller_1">
		<visual>
			<geometry>
				<mesh filename="package://last_letter/data/parameters/aircraft/quadrotor/urdf/10x4.7.stl"/>
			</geometry>
			<material name="whitePurity">
				<color rgba="1.0 1.0 1.0 1.0"/>
			</material>
		</visual>
	</link>

	<link name="propeller_2">
		<visual>
			<geometry>
				<mesh filename="package://last_letter/data/parameters/aircraft/quadrotor/urdf/10x4.7.stl"/>
			</geometry>
			<material name="whitePurity"/>
		</visual>
	</link>

	<link name="propeller_3">
		<visual>
			<geometry>
				<mesh filename="package://last_letter/data/parameters/aircraft/quadrotor/urdf/10x4.7.stl"/>
			</geometry>
			<material name="whitePurity"/>
		</visual>
	</link>

	<link name="propeller_4">
		<visual>
			<geometry>
				<mesh filename="package://last_letter/data/parameters/aircraft/quadrotor/urdf/10x4.7.stl"/>
			</geometry>
			<material name="whitePurity"/>
		</visual>
	</link>

	<joint name="motor_mount_1" type="floating">
		<parent link="base_link"/>
		<child link="propeller_1"/>
	</joint>

	<joint name="motor_mount_2" type="floating">
		<parent link="base_link"/>
		<child link="propeller_2"/>
	</joint>

	<joint name="motor_mount_3" type="floating">
		<parent link="base_link"/>
		<child link="propeller_3"/>
	</joint>

	<joint name="motor_mount_4" type="floating">
		<parent link="base_link"/>
		<child link="propeller_4"/>
	</joint>

</robot>

