<?xml version="1.0"?>

<robot name="plane">
	<link name="base_link">
		<visual>
			<geometry>
				<mesh filename="package://last_letter/data/parameters/aircraft/firefly_Y6/urdf/firefly_Y6.stl" scale="0.02621 0.02621 0.02621"/>
			</geometry>
			<material name="redYouth">
				<color rgba="1.0 0.0 0.0 1"/>
			</material>
		</visual>
	</link>

	<link name="propeller_1">
		<visual>
			<geometry>
				<mesh filename="package://last_letter/data/parameters/aircraft/firefly_Y6/urdf/10x4.7.stl"/>
			</geometry>
			<material name="whitePurity">
				<color rgba="1.0 1.0 1.0 1.0"/>
			</material>
		</visual>
	</link>

	<link name="propeller_2">
		<visual>
			<geometry>
				<mesh filename="package://last_letter/data/parameters/aircraft/firefly_Y6/urdf/10x4.7.stl"/>
			</geometry>
			<material name="whitePurity"/>
		</visual>
	</link>

	<link name="propeller_3">
		<visual>
			<geometry>
				<mesh filename="package://last_letter/data/parameters/aircraft/firefly_Y6/urdf/10x4.7.stl"/>
			</geometry>
			<material name="whitePurity"/>
		</visual>
	</link>

	<link name="propeller_4">
		<visual>
			<geometry>
				<mesh filename="package://last_letter/data/parameters/aircraft/firefly_Y6/urdf/10x4.7.stl"/>
			</geometry>
			<material name="whitePurity"/>
		</visual>
	</link>

	<link name="propeller_5">
		<visual>
			<geometry>
				<mesh filename="package://last_letter/data/parameters/aircraft/firefly_Y6/urdf/10x4.7.stl"/>
			</geometry>
			<material name="whitePurity"/>
		</visual>
	</link>

	<link name="propeller_6">
		<visual>
			<geometry>
				<mesh filename="package://last_letter/data/parameters/aircraft/firefly_Y6/urdf/10x4.7.stl"/>
			</geometry>
			<material name="whitePurity"/>
		</visual>
	</link>

	<joint name="motor_mount_1" type="floating">
		<parent link="base_link"/>
		<child link="propeller_1"/>
	</joint>

	<joint name="motor_mount_2" type="floating">
		<parent link="base_link"/>
		<child link="propeller_2"/>
	</joint>

	<joint name="motor_mount_3" type="floating">
		<parent link="base_link"/>
		<child link="propeller_3"/>
	</joint>

	<joint name="motor_mount_4" type="floating">
		<parent link="base_link"/>
		<child link="propeller_4"/>
	</joint>

	<joint name="motor_mount_5" type="floating">
		<parent link="base_link"/>
		<child link="propeller_5"/>
	</joint>

	<joint name="motor_mount_6" type="floating">
		<parent link="base_link"/>
		<child link="propeller_6"/>
	</joint>
</robot>

