<?xml version="1.0"?>

<robot name="plane">
	<link name="base_link">
		<visual>
			<origin rpy="-1.57 0.0 -1.57"/>
			<geometry>
				<mesh filename="package://last_letter/data/parameters/aircraft/tut_airplane/urdf/tut_airplane.stl" scale="0.01 0.01 0.01"/>
			</geometry>
			<material name="greenSprite">
				<color rgba="0.1 0.84 0.06 1"/>
			</material>
		</visual>
	</link>

	<link name="propeller_1">
		<visual>
			<geometry>
				<mesh filename="package://last_letter/data/parameters/aircraft/tut_airplane/urdf/10x4.7.stl"/>
			</geometry>
			<material name="whitePurity">
				<color rgba="1.0 1.0 1.0 1.0"/>
			</material>
		</visual>
	</link>

	<joint name="motor_mount" type="floating">
		<parent link="base_link"/>
		<child link="propeller_1"/>
	</joint>

</robot>
